Workbook

Sheet Altman Model
A1: Altman Z score model is a financial model formula developed by edward altman in 1968 to predict the likelyhood of a company going bankrupt, it uses multiple financial ratios to assess the financial health of a company. Altman Z score formula
A3: For Public manufacturing company | C3: Interpreting the Z score | D3: Manufacturing companies | E3: Non-manufacturing companies | F3: Emerging markets | G3: Private Manufacturing companies
A4: Z=1.2x1 + 1.4x2 + 3.3x3 + 0.6x4 + 1x5 | C4: Safe Zone(Green) | D4: >2.99 | E4: >2.90 | F4: >2.6 | G4: >2.99
A5: x1 = working capital/total assets | C5: Grey Zone | D5: >=1.81 but <=2.99 | E5: >=1.23 but <=2.90 | F5: >=1.1 but <=2.6 | G5: >=1.23 but <=2.99
A6: x2= retained earnings/total assets | C6: Distress Zone(Red) | D6: <1.81 | E6: <1.23 | F6: <1.1 | G6: <1.23
A7: x3= EBIT/Total Assets
A8: x4= Market value of equity/Total liabilities
A9: x5= Sales/Total Assets
A11: For Private Manufacturing company
A12: Z=0.717x1 + 0.847x2 + 3.107x3+ 0.420x4 + 0.998x5
A13: x1 = working capital/total assets
A14: x2= retained earnings/total assets
A15: x3= EBIT/Total Assets
A16: x4= Book value/Total liabilities
A17: x5= Sales/Total Assets
A19: For service sector companies/Non-manufacturing (including emerging markets)
A20: z= 6.56x1 + 3.26x2 + 6.72x3 + 1.05x4 + 3.25
... A27: Constant of 3.25 is added only in case of emerging markets

Sheet Sun Pharma Altman
A1: Computation of Altman Z score for Sun Pharma Industries for the Year 2023-2024 | F1: Working notes
A2: Ratio | B2: Value | C2: Weight | D2: V*W | F2: Current Assets | G2: =BS!B30 -> 149125.4
A3: x1 = working capital/total assets | B3: =G4/G6 -> 0.25491498 | C3: 1.2 | D3: =B3*C3 -> 0.30589797 | F3: Current liabilities | G3: =BS!I28 -> 44445.1
A4: x2= retained earnings/total assets | B4: =G8/G6 -> 0.31002326 | C4: 1.4 | D4: =B4*C4 -> 0.43403256 | F4: Working Capital | G4: =G2-G3 -> 104680.3
A5: x3= EBIT/Total Assets | B5: =G9/G6 -> 0.10309879 | C5: 3.3 | D5: =B5*C5 -> 0.34022599 | F5: Total Liabilities | G5: =BS!I30 -> 173703.9
A6: x4= Market value of equity/Total liabilities | B6: =G7/G5 -> 22.463362 | C6: 0.6 | D6: =B6*C6 -> 13.478017 | F6: Total Assets | G6: =BS!B32 -> 410647.9
A7: x5= Sales/Total Assets | B7: =G10/G6 -> 0.50282322 | C7: 1 | D7: =B7*C7 -> 0.50282322 | F7: Market Value | G7: =G11*G12 -> 3901973.5
A8: Z= (1.2*x1) + (1.4*x2) + (3.3*x3) + (0.6*x4) + (1*x5) | D8: =SUM(D3:D7) -> 15.060997 | F8: Retained earning | G8: =BS!J34 -> 127310.4
F9: EBIT | G9: =PnL!D15 -> 42337.3
A10: Altman Score Reverified on August 12 2025 as per https://www.alphaspread.com/security/nse/sunpharma/solvency/ratio/altman-z-score | F10: Sales | G10: =PnL!D3 -> 206483.3
F11: From stock | G11: 1626.5
F12: O/S share | G12: 2399

Sheet Profit & Loss
A1: Particulars | B1: 2024 | C1: 2023
A2: (I) Revenue from operations | B2: 202751.7 | C2: 208121.4
A3: (II) Other income | B3: 4657.6 | C3: 2790.3
A4: (III) Total income (I + II) | B4: 207409.3 | C4: 210911.7
A5: (IV) Expenses
A6: Cost of materials consumed | B6: 44293.8 | C6: 51656.3
A7: Purchases of stock-in-trade | B7: 9944.1 | C7: 11264.6
A8: Changes in inventories of finished goods, stock-in-trade and work-in-progress | B8: 1803.2 | C8: -2379.3
A9: Employee benefits expense | B9: 23739.5 | C9: 21569.5
A10: Finance costs | B10: 7840.8 | C10: 4721.8
A11: Depreciation and amortisation expense | B11: 16006.2 | C11: 16008.7
A12: Other expenses | B12: 67972.2 | C12: 61784.3
A13: Net (gain) / loss on foreign currency transactions | B13: -877.2 | C13: -502.6
A14: Total expenses (IV) | B14: 170722.6 | C14: 164123.3
A15: (V) Profit / (loss) before exceptional item and tax (III - IV) | B15: 36686.7 | C15: 46788.4
A16: (VI) Exceptional items | B16: 2190.2 | C16: 29377.9
A17: (VII) Profit / (loss) before tax (V - VI) | B17: 34496.5 | C17: 17410.5
A18: (VIII) Tax expense / (credit)
A19: Current tax | B19: 5461 | C19: 7527.7
A20: Deferred tax | B20: 453.7 | C20: -7024.4
A21: Total tax expense (VIII) | B21: 5914.7 | C21: 503.3
A22: (IX) Profit / (loss) for the year (VII - VIII) | B22: 28581.8 | C22: 16907.2
A23: (X) Other comprehensive income
A24: (A) Items that will not be reclassified to profit or loss
A25: a. Gain / (loss) on remeasurement of the defined benefit plans | B25: -305.1 | C25: 113.4
A26: Income tax on above | B26: 106.5 | C26: -39.6
A27: b. Gain / (loss) on equity instrument measured at fair value through other comprehensive income | B27: 4.8 | C27: -90.2
A28: Income tax on above | B28: -1.7 | C28: 31.5
A29: Total - (A) | B29: -195.5 | C29: 15.1
A30: (B) Items that may be reclassified to profit or loss
A31: a. Effective portion of gain / (loss) on designated portion of hedging instruments in a cash flow hedge | B31: 85.5 | C31: -192.4
A32: Income tax on above | B32: -29.8 | C32: 67.2
A33: Total - (B) | B33: 55.7 | C33: -125.2
A34: (X) Total other comprehensive income (A+B) | B34: -139.8 | C34: -110.1
A35: (XI) Total comprehensive income for the year (IX+X) | B35: 28442 | C35: 16797.1
A36: Earnings per equity share (face value per equity share - Rs1)
A37: Basic (in Rs) | B37: 11.9 | C37: 7
A38: Diluted (in Rs) | B38: 11.9 | C38: 7

Sheet Balance Sheet
A1: Particulars | B1: 2024 | C1: 2023 | E1: Particulars | F1: 2024 | G1: 2023
A2: ASSETS | E2: EQUITY AND LIABILITIES
A3: (1) Non-current assets | E3: EQUITY
A4: (a) Property plant and equipment | B4: 45391.4 | C4: 47332.5 | E4: (a) Equity share capital | F4: 2399.3 | G4: 2399.3
A5: (b) Capital work-in-progress | B5: 3882.4 | C5: 3288.7 | E5: (b) Other equity | F5: 234544.7 | G5: 235084.3
A6: (c) Goodwill | B6: 1208 | C6: 1208 | E6: Total equity | F6: 236944 | G6: 237483.6
A7: (d) Other intangible assets | B7: 30768 | C7: 38576.2
A8: (e) Intangible assets under development | B8: 3778.7 | C8: 5240.4 | E8: LIABILITY
A9: (f) Investments in the nature of equity in subsidiaries | B9: 123985.8 | C9: 123985.8 | E9: (1) Non-current liabilities
A10: (g) Investments in the nature of equity in associates | B10: 245.1 | C10: - | E10: (a) Financial liabilities
A11: (h) Financial assets | E11: (i) Borrowings | F11: 110360.1 | G11: 75867.3
A12: (i) Investments | B12: 68.8 | C12: 144 | E12: (ii) Lease liabilities | F12: 1669.1 | G12: 1815.1
A13: (ii) Loans | B13: 33869 | C13: 6327 | E13: (iii) Other financial liabilities | F13: 10772 | G13: 3912.2
A14: (iii) Other financial assets | B14: 520.4 | C14: 570.5 | E14: (b) Other non-current liabilities | F14: 4254 | G14: 5074.5
A15: (i) Deferred tax assets (Net) | B15: 9945.2 | C15: 10323.9 | E15: (c) Provisions | F15: 2197.3 | G15: 2061.6
A16: (j) Income tax assets (Net) | B16: 5033.8 | C16: 5861.3 | E16: Total non-current liabilities | F16: 129252.5 | G16: 88730.7
A17: (k) Other non-current assets | B17: 2407.2 | C17: 2365.1
A18: Total non-current assets | B18: 261103.8 | C18: 245223.4 | E18: (2) Current liabilities
E19: (a) Financial liabilities
A20: (2) Current assets | E20: (i) Borrowings | F20: 106 | G20: 59.4
A21: (a) Inventories | B21: 34236.2 | C21: 39891.9 | E21: (ii) Trade payables
A22: (b) Financial assets | E22: (a) total outstanding dues of micro and small enterprises | F22: 704.6 | G22: 1194.2
A23: (i) Investments | C23: 2002.6 | E23: (b) total outstanding dues of creditors other than micro and small enterprises | F23: 25491.2 | G23: 30061.6
A24: (ii) Trade receivables | B24: 88341.6 | C24: 71250.2 | E24: (iii) Lease liabilities | F24: 133.9 | G24: 166.4
A25: (iii) Cash and cash equivalents | B25: 3264.6 | C25: 4102.8 | E25: (iv) Other financial liabilities | F25: 7188.1 | G25: 40640.1
A26: (iv) Bank balances other than (iii) above | B26: 119.3 | C26: 110 | E26: (b) Other current liabilities | F26: 4730.5 | G26: 3437.7
A27: (v) Loans | B27: 6555.1 | C27: 33470.3 | E27: (c) Provisions | F27: 6090.8 | G27: 8095
A28: (vi) Other financial assets | B28: 7695.5 | C28: 5824 | E28: Total current liabilities | F28: 44445.1 | G28: 83654.4
A29: (c) Other current assets | B29: 8913.1 | C29: 7785.7 | E29: Liabilities directly associated with assets classified as held for sale | F29: 6.3 | G29: 6.2
A30: Total current assets | B30: 149125.4 | C30: 164437.5 | E30: Total liabilities | F30: 173703.9 | G30: 172391.3
A31: Assets classified as held for sale | B31: 418.7 | C31: 214 | E31: TOTAL EQUITY AND LIABILITIES | F31: 410647.9 | G31: 409874.9
A32: TOTAL ASSETS | B32: 410647.9 | C32: 409874.9

Sheet Cashflow
A1: Particulars | B1: 2024 | C1: 2023 | E1: Notes:
A2: A. Cash flow from operating activities | E2: 1. Cash and cash equivalents comprises of
A3: Profit / (loss) before tax | B3: 34496.5 | C3: 17410.5 | E3: Particulars | F3: 2024 | G3: 2023
A4: Adjustments for: | E4: Balances with banks
A5: Depreciation and amortisation expense | B5: 16006.2 | C5: 16008.7 | E5: In current accounts | F5: 3252.7 | G5: 4086.6
A6: Net (gain) / loss on sale / write off / impairment of property/ plant and equipment/ other intangible assets and intangible assets under development | B6: 1707.1 | C6: 40.4 | E6: Cash on hand | F6: 11.9 | G6: 16.2
A7: (Gain) / loss on derecognition of Right-of-use assets | B7: -1.3 | C7: -0.4 | E7: Cash and cash equivalents in statement of cash flow (Refer Note 15) | F7: 3264.6 | G7: 4102.8
A8: Finance costs | B8: 7840.8 | C8: 4721.8
A9: Interest income | B9: -3964.3 | C9: -2202 | E9: 2. Change in financial liability / asset arising from financing activities
A10: Net (gain) / loss arising on financial assets measured at fair value through profit or loss | B10: - | C10: -2.2 | E10: Particulars | F10: 2024 | G10: 2023
A11: Net (gain) / loss on sale of financial assets measured at fair value through profit or loss | B11: -220.3 | C11: -173 | E11: Borrowings Borrowings
A12: Provision / write off / (reversal) for doubtful trade receivables / advances | B12: 119.5 | C12: 242.5 | E12: Opening balance | F12: 75926.7 | G12: 48687.1
A13: Sundry balances written back net | B13: -215.6 | C13: -128.5 | E13: Changes from financing cash flows | F13: 34539.4 | G13: 27239.6
A14: Write off of investment due to dissolution of subsidiary | B14: - | C14: 8.8 | E14: Closing balance | F14: 110466.1 | G14: 75926.7
A15: Impairment in value of investment | B15: - | C15: 29377.9
A16: Effect of exchange rate changes | B16: -3583 | C16: 340
A17: Operating profit / (loss) before working capital changes | B17: 52185.6 | C17: 65644.5
A18: Movements in working capital:
A19: (Increase) / decrease in inventories | B19: 5655.7 | C19: -5854.5
A20: (Increase) / decrease in trade receivables | B20: -14771.4 | C20: -29320.1
A21: (Increase) / decrease in other assets | B21: -2764.5 | C21: -825.3
A22: Increase / (decrease) in trade payables | B22: -4136.3 | C22: 4063.6
A23: Increase / (decrease) in other liabilities | B23: -33503.1 | C23: -4985.7
A24: Increase / (decrease) in provisions | B24: -2171.5 | C24: -19331.8
A25: Cash generated from / (used in) operations | B25: 494.5 | C25: 9390.7
A26: Net Income tax (paid) / refund received (including interest on refunds) | B26: -3418.7 | C26: -4319.9
A27: Net cash generated from / (used in) operating activities (A) | B27: -2924.2 | C27: 5070.8
A29: B. Cash flow from investing activities
A30: Payments for purchase of property plant and equipment (including capital work-in-progress other intangible assets and intangible assets under development) | B30: -7492.4 | C30: -9624.3
A31: Proceeds from disposal of property plant and equipment and other intangible assets | B31: 147.2 | C31: 83
A32: Loans / Inter corporate deposits
A33: Given to / placed
A34: Subsidiary companies | B34: -15.3 | C34: -159.2
A35: Received back / matured from
A36: Subsidiary companies | B36: - | C36: 60
A37: Purchase of investments
A38: Associate | B38: -165.1 | C38: -
A39: Others | B39: -28169.6 | C39: -36929.5
A40: Proceeds from sale of investments
A41: Others | B41: 30392.5 | C41: 36952.5
...

Sheet BS
A1: Particulars | B1: 2024 | C1: percentage | D1: 2023 | E1: percentage | H1: Particulars | I1: 2024 | J1: percentage | K1: 2023 | L1: percentage
A2: ASSETS | H2: EQUITY AND LIABILITIES
A3: (1) Non-current assets | H3: EQUITY
A4: (a) Property plant and equipment | B4: 45391.4 | C4: =B4/$B$32 -> 0.11053606 | D4: 47332.5 | E4: =D4/$D$32 -> 0.11548036 | H4: (a) Equity share capital | I4: 2399.3 | J4: =I4/$I$31 -> 0.0058427183 | K4: 2399.3 | L4: =K4/$K$31 -> 0.0058537373
A5: (b) Capital work-in-progress | B5: 3882.4 | C5: =B5/$B$32 -> 0.0094543281 | D5: 3288.7 | E5: =D5/$D$32 -> 0.0080236677 | H5: (b) Other equity | I5: 234544.7 | J5: =I5/$I$31 -> 0.57115768 | K5: 235084.3 | L5: =K5/$K$31 -> 0.57355134
A6: (c) Goodwill | B6: 1208 | C6: =B6/$B$32 -> 0.0029416929 | D6: 1208 | E6: =D6/$D$32 -> 0.0029472407 | H6: Total equity | I6: 236944 | J6: =I6/$I$31 -> 0.57700039 | K6: 237483.6 | L6: =K6/$K$31 -> 0.57940508
A7: (d) Other intangible assets | B7: 30768 | C7: =B7/$B$32 -> 0.074925502 | D7: 38576.2 | E7: =D7/$D$32 -> 0.09411701
A8: (e) Intangible assets under development | B8: 3778.7 | C8: =B8/$B$32 -> 0.0092018004 | D8: 5240.4 | E8: =D8/$D$32 -> 0.012785365 | H8: LIABILITY
A9: (f) Investments in the nature of equity in subsidiaries | B9: 123985.8 | C9: =B9/$B$32 -> 0.30192727 | D9: 123985.8 | E9: =D9/$D$32 -> 0.30249669 | H9: (1) Non-current liabilities
A10: (g) Investments in the nature of equity in associates | B10: 245.1 | C10: =B10/$B$32 -> 0.00059686169 | D10: - | H10: (a) Financial liabilities
A11: (h) Financial assets | H11: (i) Borrowings | I11: 110360.1 | J11: =I11/$I$31 -> 0.26874629 | K11: 75867.3 | L11: =K11/$K$31 -> 0.18509867
A12: (i) Investments | B12: 68.8 | C12: =B12/$B$32 -> 0.00016754012 | D12: 144 | E12: =D12/$D$32 -> 0.00035132671 | H12: (ii) Lease liabilities | I12: 1669.1 | J12: =I12/$I$31 -> 0.0040645526 | K12: 1815.1 | L12: =K12/$K$31 -> 0.0044284244
A13: (ii) Loans | B13: 33869 | C13: =B13/$B$32 -> 0.082476983 | D13: 6327 | E13: =D13/$D$32 -> 0.015436417 | H13: (iii) Other financial liabilities | I13: 10772 | J13: =I13/$I$31 -> 0.026231718 | K13: 3912.2 | L13: =K13/$K$31 -> 0.0095448636
A14: (iii) Other financial assets | B14: 520.4 | C14: =B14/$B$32 -> 0.0012672657 | D14: 570.5 | E14: =D14/$D$32 -> 0.0013918881 | H14: (b) Other non-current liabilities | I14: 4254 | J14: =I14/$I$31 -> 0.01035924 | K14: 5074.5 | L14: =K14/$K$31 -> 0.012380607
A15: (i) Deferred tax assets (Net) | B15: 9945.2 | C15: =B15/$B$32 -> 0.024218315 | D15: 10323.9 | E15: =D15/$D$32 -> 0.025187929 | H15: (c) Provisions | I15: 2197.3 | J15: =I15/$I$31 -> 0.0053508127 | K15: 2061.6 | L15: =K15/$K$31 -> 0.0050298274
A16: (j) Income tax assets (Net) | B16: 5033.8 | C16: =B16/$B$32 -> 0.01225819 | D16: 5861.3 | E16: =D16/$D$32 -> 0.014300217 | H16: Total non-current liabilities | I16: 129252.5 | J16: =I16/$I$31 -> 0.31475261 | K16: 88730.7 | L16: =K16/$K$31 -> 0.21648239
A17: (k) Other non-current assets | B17: 2407.2 | C17: =B17/$B$32 -> 0.0058619562 | D17: 2365.1 | E17: =D17/$D$32 -> 0.0057702972
A18: Total non-current assets | B18: 261103.8 | C18: =B18/$B$32 -> 0.63583376 | D18: 245223.4 | E18: =D18/$D$32 -> 0.5982884 | H18: (2) Current liabilities
H19: (a) Financial liabilities
A20: (2) Current assets | H20: (i) Borrowings | I20: 106 | J20: =I20/$I$31 -> 0.00025812868 | K20: 59.4 | L20: =K20/$K$31 -> 0.00014492227
A21: (a) Inventories | B21: 34236.2 | C21: =B21/$B$32 -> 0.08337118 | D21: 39891.9 | E21: =D21/$D$32 -> 0.097327014 | H21: (ii) Trade payables
A22: (b) Financial assets | E22: =D22/$D$32 -> 0 | H22: (a) total outstanding dues of micro and small enterprises | I22: 704.6 | J22: =I22/$I$31 -> 0.0017158252 | K22: 1194.2 | L22: =K22/$K$31 -> 0.0029135719
A23: (i) Investments | D23: 2002.6 | E23: =D23/$D$32 -> 0.004885881 | H23: (b) total outstanding dues of creditors other than micro and small enterprises | I23: 25491.2 | J23: =I23/$I$31 -> 0.062075564 | K23: 30061.6 | L23: =K23/$K$31 -> 0.073343354
A24: (ii) Trade receivables | B24: 88341.6 | C24: =B24/$B$32 -> 0.21512736 | D24: 71250.2 | E24: =D24/$D$32 -> 0.17383402 | H24: (iii) Lease liabilities | I24: 133.9 | J24: =I24/$I$31 -> 0.0003260701 | K24: 166.4 | L24: =K24/$K$31 -> 0.00040597753
A25: (iii) Cash and cash equivalents | B25: 3264.6 | C25: =B25/$B$32 -> 0.0079498763 | D25: 4102.8 | E25: =D25/$D$32 -> 0.010009884 | H25: (iv) Other financial liabilities | I25: 7188.1 | J25: =I25/$I$31 -> 0.01750429 | K25: 40640.1 | L25: =K25/$K$31 -> 0.099152449
A26: (iv) Bank balances other than (iii) above | B26: 119.3 | C26: =B26/$B$32 -> 0.00029051652 | D26: 110 | E26: =D26/$D$32 -> 0.00026837457 | H26: (b) Other current liabilities | I26: 4730.5 | J26: =I26/$I$31 -> 0.011519601 | K26: 3437.7 | L26: =K26/$K$31 -> 0.0083871933
A27: (v) Loans | B27: 6555.1 | C27: =B27/$B$32 -> 0.015962824 | D27: 33470.3 | E27: =D27/$D$32 -> 0.081659794 | H27: (c) Provisions | I27: 6090.8 | J27: =I27/$I$31 -> 0.014832171 | K27: 8095 | L27: =K27/$K$31 -> 0.019749929
A28: (vi) Other financial assets | B28: 7695.5 | C28: =B28/$B$32 -> 0.018739899 | D28: 5824 | E28: =D28/$D$32 -> 0.014209214 | H28: Total current liabilities | I28: 44445.1 | J28: =I28/$I$31 -> 0.10823165 | K28: 83654.4 | L28: =K28/$K$31 -> 0.2040974
A29: (c) Other current assets | B29: 8913.1 | C29: =B29/$B$32 -> 0.021704969 | D29: 7785.7 | E29: =D29/$D$32 -> 0.018995308 | H29: Liabilities directly associated with assets classified as held for sale | I29: 6.3 | J29: =I29/$I$31 -> 1.534161e-05 | K29: 6.2 | L29: =K29/$K$31 -> 1.5126567e-05
A30: Total current assets | B30: 149125.4 | C30: =B30/$B$32 -> 0.36314663 | D30: 164437.5 | E30: =D30/$D$32 -> 0.40118948 | H30: Total liabilities | I30: 173703.9 | J30: =I30/$I$31 -> 0.42299961 | K30: 172391.3 | L30: =K30/$K$31 -> 0.42059492
A31: Assets classified as held for sale | B31: 418.7 | C31: =B31/$B$32 -> 0.0010196083 | D31: 214 | E31: =D31/$D$32 -> 0.00052211053 | H31: TOTAL EQUITY AND LIABILITIES | I31: 410647.9 | J31: =I31/$I$31 -> 1 | K31: 409874.9 | L31: =K31/$K$31 -> 1
A32: TOTAL ASSETS | B32: 410647.9 | C32: =B32/$B$32 -> 1 | D32: 409874.9 | E32: =D32/$D$32 -> 1
I34: Retained Earnings | J34: 127310.4

Sheet PnL
A2: Particular | B2: 2023 | C2: % Change | D2: 2024 | E2: % Change
A3: Revenue from Operations | B3: 213793.6 | C3: =1 -> 1 | D3: 206483.3 | E3: =1 -> 1
A4: Less: COGS
A5: Raw Materials | B5: 62920.9 | C5: =B5/$B$3 -> 0.29430675 | D5: 54237.9 | E5: =D5/$D$3 -> 0.26267451
A6: Power & Fuel Cost | B6: 4952.1 | C6: =B6/$B$3 -> 0.023162995 | D6: 4504.2 | E6: =D6/$D$3 -> 0.021813871
A7: Employee Cost | B7: 21569.5 | C7: =B7/$B$3 -> 0.10088936 | D7: 23739.5 | E7: =D7/$D$3 -> 0.11497056
A8: Other Manufacturing Expenses | B8: 10373.2 | C8: =B8/$B$3 -> 0.048519694 | D8: 11953 | E8: =D8/$D$3 -> 0.057888459
A9: Gross Profit | B9: =B3-SUM(B5:B8) -> 113977.9 | C9: =B9/$B$3 -> 0.5331212 | D9: =D3-SUM(D5:D8) -> 112048.7 | E9: =D9/$D$3 -> 0.5426526
A10: Less: Cash Operating Expenses
A11: Selling and Administration Expenses | B11: 43264.2 | C11: =B11/$B$3 -> 0.20236434 | D11: 47548.6 | E11: =D11/$D$3 -> 0.23027819
A12: Miscellaneous Expenses | B12: 32572.7 | C12: =B12/$B$3 -> 0.15235582 | D12: 6156.6 | E12: =D12/$D$3 -> 0.029816455
A13: EBITDA | B13: =B9-B12-B11 -> 38141 | C13: =B13/$B$3 -> 0.17840104 | D13: =D9-D12-D11 -> 58343.5 | E13: =D13/$D$3 -> 0.28255796
A14: Less: Depreciation and amortization | B14: 16008.7 | C14: =B14/$B$3 -> 0.074879229 | D14: 16006.2 | E14: =D14/$D$3 -> 0.077518133
A15: EBIT | B15: =B13-B14 -> 22132.3 | C15: =B15/$B$3 -> 0.10352181 | D15: =D13-D14 -> 42337.3 | E15: =D15/$D$3 -> 0.20503983
A16: Less: Interest/Finance cost | B16: 4721.8 | C16: =B16/$B$3 -> 0.022085787 | D16: 7840.8 | E16: =D16/$D$3 -> 0.037973047
A17: EBT | B17: =B15-B16 -> 17410.5 | C17: =B17/$B$3 -> 0.081436021 | D17: =D15-D16 -> 34496.5 | E17: =D17/$D$3 -> 0.16706678
A18: Less: Tax
A19: Tax | B19: 7527.7 | C19: =B19/$B$3 -> 0.035210128 | D19: 5461 | E19: =D19/$D$3 -> 0.026447659
A20: Deferred Tax | B20: -7024.4 | C20: =B20/$B$3 -> -0.032855988 | D20: 453.7 | E20: =D20/$D$3 -> 0.0021972721
A21: Net profit/EAT | B21: =B17-B19-B20 -> 16907.2 | C21: =B21/$B$3 -> 0.079081881 | D21: =D17-D19-D20 -> 28581.8 | E21: =D21/$D$3 -> 0.13842185
